Workbook

Sheet Qwen_Final
A1: Screen ID | B1: Phase 1 – UI Perception | D1: Phase 2 – Source Test Generation | F1: Phase 3 – MR Generation | H1: Phase 4 – MR Prioritization | J1: Phase 5 – Execution Scheduling
B2: Energy (kWh) | C2: Carbon Emissions (kg CO₂eq) | D2: Energy (kWh) | E2: Carbon Emissions (kg CO₂eq) | F2: Energy (kWh) | G2: Carbon Emissions (kg CO₂eq) | H2: Energy (kWh) | I2: Carbon Emissions (kg CO₂eq) | J2: Energy (kWh) | K2: Carbon Emissions (kg CO₂eq)
B3: Run 1 | C3: Run 1 | D3: Run 1 | E3: Run 1 | F3: Run 1 | G3: Run 1 | H3: Run 1 | I3: Run 1 | J3: Run 1 | K3: Run 1
A4: 10214 | B4: 0.001209 | C4: 0.00075902 | D4: 0.000659 | E4: 0.00041376 | F4: 0.000887 | G4: 0.0005567 | H4: 0.000922 | I4: 0.00057865 | J4: 0.000397 | K4: 0.00024912
A5: 1028 | B5: 0.001745 | C5: 0.0010955 | D5: 0.007941 | E5: 0.00498461 | F5: 0.004421 | G5: 0.00277465 | H5: 0.006766 | I5: 0.0042468 | J5: 0.002236 | K5: 0.0014035
A6: 10440 | B6: 0.001265 | C6: 0.00079418 | D6: 0.004514 | E6: 0.00283302 | F6: 0.002834 | G6: 0.00177906 | H6: 0.006129 | I6: 0.00384732 | J6: 0.001971 | K6: 0.00123726
A7: 10498 | B7: 0.001375 | C7: 0.00086328 | D7: 0.002549 | E7: 0.00159981 | F7: 0.002107 | G7: 0.0013226 | H7: 0.003289 | I7: 0.00206459 | J7: 0.001088 | K7: 0.00068289
A8: 10538 | B8: 0.001702 | C8: 0.00106813 | D8: 0.004157 | E8: 0.00260926 | F8: 0.005032 | G8: 0.0031587 | H8: 0.001383 | I8: 0.00086804 | J8: 0.000583 | K8: 0.00036617
A9: 10592 | B9: 0.001339 | C9: 0.00084043 | D9: 0.001184 | E9: 0.00074326 | F9: 0.001787 | G9: 0.00112177 | H9: 0.002283 | I9: 0.00143271 | J9: 0.000893 | K9: 0.00056063
A10: 10612 | B10: 0.002026 | C10: 0.0012717 | D10: 0.004405 | E10: 0.00276466 | F10: 0.003584 | G10: 0.00224963 | H10: 0.004077 | I10: 0.00255931 | J10: 0.001587 | K10: 0.00099594
A11: 10636 | B11: 0.001675 | C11: 0.00105158 | D11: 0.003716 | E11: 0.00233246 | F11: 0.002316 | G11: 0.0014538 | H11: 0.004693 | I11: 0.00294554 | J11: 0.00164 | K11: 0.00102963
A12: 1074 | B12: 0.001555 | C12: 0.00097615 | D12: 0.003765 | E12: 0.00236327 | F12: 0.002253 | G12: 0.00141424 | H12: 0.001933 | I12: 0.00121326 | J12: 0.000798 | K12: 0.00050119
A13: 10743 | B13: 0.00154 | C13: 0.00096672 | D13: 0.004628 | E13: 0.002905 | F13: 0.002641 | G13: 0.00165747 | H13: 0.001081 | I13: 0.00067843 | J13: 0.000476 | K13: 0.00029884
A14: 10798 | B14: 0.001588 | C14: 0.00099681 | D14: 0.00589 | E14: 0.00369703 | F14: 0.005187 | G14: 0.00325557 | H14: 0.003962 | I14: 0.00248694 | J14: 0.001576 | K14: 0.00098924
A15: 11039 | B15: 0.00168 | C15: 0.00105455 | D15: 0.003142 | E15: 0.00197208 | F15: 0.003098 | G15: 0.00194437 | H15: 0.002989 | I15: 0.00187629 | J15: 0.001153 | K15: 0.00072388
... A503: 9910 | B503: 0.001465 | C503: 0.00091973 | D503: 0.003572 | E503: 0.00224233 | F503: 0.000957 | G503: 0.00060076 | H503: 0.000901 | I503: 0.00056525 | J503: 0.0004 | K503: 0.00025111

Sheet Phi_Final
A1: Screen ID | B1: Phase 1 – UI Perception | D1: Phase 2 – Source Test Generation | F1: Phase 3 – MR Generation | H1: Phase 4 – MR Prioritization | J1: Phase 5 – Execution Scheduling
B2: Energy (kWh) | C2: Carbon Emissions (kg CO₂eq) | D2: Energy (kWh) | E2: Carbon Emissions (kg CO₂eq) | F2: Energy (kWh) | G2: Carbon Emissions (kg CO₂eq) | H2: Energy (kWh) | I2: Carbon Emissions (kg CO₂eq) | J2: Energy (kWh) | K2: Carbon Emissions (kg CO₂eq)
B3: Run 1 | C3: Run 1 | D3: Run 1 | E3: Run 1 | F3: Run 1 | G3: Run 1 | H3: Run 1 | I3: Run 1 | J3: Run 1 | K3: Run 1
A4: 10214 | B4: 0.001337 | C4: 0.00083944 | D4: 0.002476 | E4: 0.00155403 | F4: 0.002294 | G4: 0.00144018 | H4: 0.001354 | I4: 0.00084993 | J4: 0.000729 | K4: 0.00045742
A5: 1028 | B5: 0.001574 | C5: 0.00098781 | D5: 0.00313 | E5: 0.00196474 | F5: 0.003523 | G5: 0.00221138 | H5: 0.002572 | I5: 0.00161441 | J5: 0.001374 | K5: 0.00086229
A6: 10440 | B6: 0.001613 | C6: 0.00101268 | D6: 0.003446 | E6: 0.00216268 | F6: 0.002334 | G6: 0.00146479 | H6: 0.000918 | I6: 0.0005763 | J6: 0.00067 | K6: 0.00042025
A7: 10498 | B7: 0.00015 | C7: 9.405e-05 | D7: 0.001627 | E7: 0.00102093 | F7: 0.003553 | G7: 0.00223004 | H7: 1.7e-05 | I7: 1.085e-05 | J7: 1.7e-05 | K7: 1.069e-05
A8: 10538 | B8: 0.001639 | C8: 0.00102858 | D8: 0.002498 | E8: 0.00156777 | F8: 0.002789 | G8: 0.00175083 | H8: 1.8e-05 | I8: 1.105e-05 | J8: 1.7e-05 | K8: 1.071e-05
A9: 10592 | B9: 0.001444 | C9: 0.00090667 | D9: 0.002828 | E9: 0.00177489 | F9: 0.003333 | G9: 0.00209192 | H9: 0.001834 | I9: 0.00115112 | J9: 0.001086 | K9: 0.00068194
A10: 10612 | B10: 0.002347 | C10: 0.0014729 | D10: 0.003093 | E10: 0.00194114 | F10: 0.003819 | G10: 0.00239706 | H10: 0.00245 | I10: 0.0015375 | J10: 0.001303 | K10: 0.00081765
A11: 10636 | B11: 0.002318 | C11: 0.00145519 | D11: 0.003309 | E11: 0.00207706 | F11: 0.005212 | G11: 0.0032713 | H11: 0.001127 | I11: 0.00070708 | J11: 0.000701 | K11: 0.00044027
A12: 1074 | B12: 0.002019 | C12: 0.00126707 | D12: 0.00296 | E12: 0.00185782 | F12: 0.010344 | G12: 0.00649282 | H12: 0.001966 | I12: 0.00123395 | J12: 0.001129 | K12: 0.00070849
A13: 10743 | B13: 0.00196 | C13: 0.00123002 | D13: 0.002752 | E13: 0.00172734 | F13: 0.003191 | G13: 0.00200262 | H13: 0.001307 | I13: 0.00082067 | J13: 0.000718 | K13: 0.00045058
A14: 10798 | B14: 0.001572 | C14: 0.0009864 | D14: 0.002175 | E14: 0.00136512 | F14: 0.002626 | G14: 0.00164848 | H14: 0.001401 | I14: 0.00087945 | J14: 0.000826 | K14: 0.00051874
A15: 11039 | B15: 0.001685 | C15: 0.00105737 | D15: 0.003465 | E15: 0.00217514 | F15: 0.005068 | G15: 0.00318122 | H15: 0.002431 | I15: 0.00152571 | J15: 0.001305 | K15: 0.00081891
... A503: 9910 | B503: 0.001611 | C503: 0.00101095 | D503: 0.002983 | E503: 0.00187251 | F503: 0.003701 | G503: 0.00232279 | H503: 0.001323 | I503: 0.0008302 | J503: 0.000704 | K503: 0.00044191

Sheet InternVL_InternLM
A1: Screen ID | B1: Phase 1 – UI Perception | D1: Phase 2 – Source Test Generation | F1: Phase 3 – MR Generation | H1: Phase 4 – MR Prioritization | J1: Phase 5 – Execution Scheduling
B2: Energy (kWh) | C2: Carbon Emissions (kg CO₂eq) | D2: Energy (kWh) | E2: Carbon Emissions (kg CO₂eq) | F2: Energy (kWh) | G2: Carbon Emissions (kg CO₂eq) | H2: Energy (kWh) | I2: Carbon Emissions (kg CO₂eq) | J2: Energy (kWh) | K2: Carbon Emissions (kg CO₂eq)
B3: Run 1 | C3: Run 1 | D3: Run 1 | E3: Run 1 | F3: Run 1 | G3: Run 1 | H3: Run 1 | I3: Run 1 | J3: Run 1 | K3: Run 1
A4: 10214 | B4: 0.001448 | C4: 0.00090866 | D4: 0.013575 | E4: 0.00852063 | F4: 0.001502 | G4: 0.00094296 | H4: 0.00088 | I4: 0.00055238 | J4: 0.000597 | K4: 0.0003746
A5: 1028 | B5: 0.001698 | C5: 0.00106589 | D5: 0.004232 | E5: 0.00265633 | F5: 0.005241 | G5: 0.00328991 | H5: 0.004226 | I5: 0.00265246 | J5: 0.002145 | K5: 0.00134621
A6: 10440 | B6: 0.00181 | C6: 0.00113628 | D6: 0.00613 | E6: 0.00384777 | F6: 0.004828 | G6: 0.00303044 | H6: 0.002278 | I6: 0.00142966 | J6: 0.001184 | K6: 0.00074326
A7: 10498 | B7: 0.001836 | C7: 0.00115256 | D7: 0.004947 | E7: 0.00310527 | F7: 0.004039 | G7: 0.00253499 | H7: 1.7e-05 | I7: 1.083e-05 | J7: 1.7e-05 | K7: 1.07e-05
A8: 10538 | B8: 0.00181 | C8: 0.00113635 | D8: 0.004364 | E8: 0.00273934 | F8: 0.022586 | G8: 0.01417683 | H8: 1.8e-05 | I8: 1.159e-05 | J8: 1.8e-05 | K8: 1.123e-05
A9: 10592 | B9: 0.001181 | C9: 0.000741 | D9: 0.00372 | E9: 0.00233492 | F9: 0.004597 | G9: 0.00288528 | H9: 0.001897 | I9: 0.00119076 | J9: 0.001197 | K9: 0.00075108
A10: 10612 | B10: 0.001715 | C10: 0.00107634 | D10: 0.005114 | E10: 0.00320962 | F10: 0.002727 | G10: 0.00171136 | H10: 0.001197 | I10: 0.00075119 | J10: 0.000502 | K10: 0.0003151
A11: 10636 | B11: 0.001574 | C11: 0.00098769 | D11: 0.014262 | E11: 0.00895213 | F11: 0.001212 | G11: 0.00076052 | H11: 0.000513 | I11: 0.00032194 | J11: 0.000314 | K11: 0.00019688
A12: 1074 | B12: 0.001554 | C12: 0.00097533 | D12: 0.001654 | E12: 0.00103809 | F12: 0.001651 | G12: 0.00103608 | H12: 0.002211 | I12: 0.00138807 | J12: 0.001149 | K12: 0.00072093
A13: 10743 | B13: 0.00166 | C13: 0.00104183 | D13: 0.003869 | E13: 0.00242826 | F13: 0.001105 | G13: 0.00069331 | H13: 1.7e-05 | I13: 1.072e-05 | J13: 1.7e-05 | K13: 1.065e-05
A14: 10798 | B14: 0.001723 | C14: 0.00108143 | D14: 0.002822 | E14: 0.00177161 | F14: 0.02275 | G14: 0.01427945 | H14: 1.7e-05 | I14: 1.093e-05 | J14: 1.8e-05 | K14: 1.108e-05
A15: 11039 | B15: 0.001812 | C15: 0.00113716 | D15: 0.004148 | E15: 0.00260348 | F15: 0.00126 | G15: 0.00079113 | H15: 1.7e-05 | I15: 1.057e-05 | J15: 1.7e-05 | K15: 1.057e-05
... A503: 9910 | B503: 0.00162 | C503: 0.00101666 | D503: 0.006423 | E503: 0.00403186 | F503: 0.001001 | G503: 0.00062847 | H503: 1.7e-05 | I503: 1.089e-05 | J503: 1.7e-05 | K503: 1.066e-05

Sheet InternVL_Mistral
A1: Screen ID | B1: Phase 1 – UI Perception | D1: Phase 2 – Source Test Generation | F1: Phase 3 – MR Generation | H1: Phase 4 – MR Prioritization | J1: Phase 5 – Execution Scheduling
B2: Energy (kWh) | C2: Carbon Emissions (kg CO₂eq) | D2: Energy (kWh) | E2: Carbon Emissions (kg CO₂eq) | F2: Energy (kWh) | G2: Carbon Emissions (kg CO₂eq) | H2: Energy (kWh) | I2: Carbon Emissions (kg CO₂eq) | J2: Energy (kWh) | K2: Carbon Emissions (kg CO₂eq)
B3: Run 1 | C3: Run 1 | D3: Run 1 | E3: Run 1 | F3: Run 1 | G3: Run 1 | H3: Run 1 | I3: Run 1 | J3: Run 1 | K3: Run 1
A4: 10214 | B4: 0.001368 | C4: 0.00085861 | D4: 0.005203 | E4: 0.00326575 | F4: 0.003547 | G4: 0.00222647 | H4: 0.00224 | I4: 0.00140574 | J4: 0.001226 | K4: 0.00076983
A5: 1028 | B5: 0.001671 | C5: 0.00104904 | D5: 0.004327 | E5: 0.00271592 | F5: 0.001599 | G5: 0.00100384 | H5: 0.001238 | I5: 0.00077737 | J5: 0.000593 | K5: 0.00037241
A6: 10440 | B6: 0.001801 | C6: 0.00113042 | D6: 0.005018 | E6: 0.0031497 | F6: 0.001478 | G6: 0.00092783 | H6: 0.000512 | I6: 0.00032127 | J6: 0.000411 | K6: 0.00025804
A7: 10498 | B7: 0.001825 | C7: 0.00114536 | D7: 0.004641 | E7: 0.00291313 | F7: 0.003068 | G7: 0.0019257 | H7: 0.001934 | I7: 0.00121379 | J7: 0.000938 | K7: 0.00058858
A8: 10538 | B8: 0.001832 | C8: 0.00115005 | D8: 0.008461 | E8: 0.00531055 | F8: 0.002227 | G8: 0.00139782 | H8: 0.001917 | I8: 0.001203 | J8: 0.000885 | K8: 0.00055529
A9: 10592 | B9: 0.001217 | C9: 0.00076386 | D9: 0.005163 | E9: 0.00324079 | F9: 0.00275 | G9: 0.00172622 | H9: 0.0026 | I9: 0.00163191 | J9: 0.00137 | K9: 0.00085968
A10: 10612 | B10: 0.001699 | C10: 0.00106643 | D10: 0.005635 | E10: 0.00353682 | F10: 0.005533 | G10: 0.00347307 | H10: 0.00174 | I10: 0.00109206 | J10: 0.00108 | K10: 0.00067776
A11: 10636 | B11: 0.001616 | C11: 0.00101445 | D11: 0.005071 | E11: 0.00318296 | F11: 0.001097 | G11: 0.00068879 | H11: 0.000936 | I11: 0.00058749 | J11: 0.00043 | K11: 0.00026979
A12: 1074 | B12: 0.001576 | C12: 0.00098913 | D12: 0.00594 | E12: 0.00372818 | F12: 0.002338 | G12: 0.00146723 | H12: 0.002244 | I12: 0.00140873 | J12: 0.001387 | K12: 0.00087079
A13: 10743 | B13: 0.001688 | C13: 0.00105954 | D13: 0.004122 | E13: 0.00258719 | F13: 0.001233 | G13: 0.00077413 | H13: 0.00092 | I13: 0.00057767 | J13: 0.000468 | K13: 0.00029383
A14: 10798 | B14: 0.001782 | C14: 0.00111826 | D14: 0.003584 | E14: 0.00224942 | F14: 0.001636 | G14: 0.00102685 | H14: 0.000507 | I14: 0.00031814 | J14: 0.000399 | K14: 0.00025032
A15: 11039 | B15: 0.001836 | C15: 0.00115253 | D15: 0.006227 | E15: 0.00390828 | F15: 0.000851 | G15: 0.00053414 | H15: 1.8e-05 | I15: 1.113e-05 | J15: 1.7e-05 | K15: 1.075e-05
... A503: 9910 | B503: 0.00167 | C503: 0.00104822 | D503: 0.003081 | E503: 0.00193368 | F503: 0.001175 | G503: 0.00073752 | H503: 0.000812 | I503: 0.00050938 | J503: 0.000508 | K503: 0.00031871

Sheet InternVL_Llama
A1: Screen ID | B1: Phase 1 – UI Perception | D1: Phase 2 – Source Test Generation | F1: Phase 3 – MR Generation | H1: Phase 4 – MR Prioritization | J1: Phase 5 – Execution Scheduling
B2: Energy (kWh) | C2: Carbon Emissions (kg CO₂eq) | D2: Energy (kWh) | E2: Carbon Emissions (kg CO₂eq) | F2: Energy (kWh) | G2: Carbon Emissions (kg CO₂eq) | H2: Energy (kWh) | I2: Carbon Emissions (kg CO₂eq) | J2: Energy (kWh) | K2: Carbon Emissions (kg CO₂eq)
B3: Run 1 | C3: Run 1 | D3: Run 1 | E3: Run 1 | F3: Run 1 | G3: Run 1 | H3: Run 1 | I3: Run 1 | J3: Run 1 | K3: Run 1
A4: 10214 | B4: 0.001546 | C4: 0.00097051 | D4: 0.002504 | E4: 0.00157146 | F4: 0.009674 | G4: 0.00607227 | H4: 0.00242 | I4: 0.00151871 | J4: 0.000967 | K4: 0.00060713
A5: 1028 | B5: 0.001767 | C5: 0.00110911 | D5: 0.004781 | E5: 0.00300104 | F5: 0.012585 | G5: 0.00789927 | H5: 0.004449 | I5: 0.00279252 | J5: 0.002475 | K5: 0.00155381
A6: 10440 | B6: 0.002067 | C6: 0.0012974 | D6: 0.002441 | E6: 0.00153218 | F6: 0.004542 | G6: 0.00285106 | H6: 0.002279 | I6: 0.00143064 | J6: 0.000855 | K6: 0.0005364
A7: 10498 | B7: 0.002116 | C7: 0.00132815 | D7: 0.003306 | E7: 0.00207531 | F7: 0.006291 | G7: 0.00394847 | H7: 0.002489 | I7: 0.00156215 | J7: 0.001063 | K7: 0.00066712
A8: 10538 | B8: 0.00203 | C8: 0.001274 | D8: 0.002953 | E8: 0.00185325 | F8: 0.008128 | G8: 0.00510166 | H8: 0.002426 | I8: 0.0015225 | J8: 0.000991 | K8: 0.00062196
A9: 10592 | B9: 0.001396 | C9: 0.00087633 | D9: 0.002183 | E9: 0.00137016 | F9: 0.004638 | G9: 0.00291109 | H9: 0.002079 | I9: 0.00130502 | J9: 0.000989 | K9: 0.00062108
A10: 10612 | B10: 0.00185 | C10: 0.00116133 | D10: 0.002729 | E10: 0.00171296 | F10: 0.014127 | G10: 0.00886699 | H10: 0.00331 | I10: 0.00207788 | J10: 0.001174 | K10: 0.00073704
A11: 10636 | B11: 0.001791 | C11: 0.0011243 | D11: 0.002446 | E11: 0.00153554 | F11: 0.006903 | G11: 0.00433306 | H11: 0.001265 | I11: 0.00079425 | J11: 0.000673 | K11: 0.00042253
A12: 1074 | B12: 0.001666 | C12: 0.00104555 | D12: 0.002118 | E12: 0.0013293 | F12: 0.002861 | G12: 0.00179561 | H12: 0.001307 | I12: 0.0008203 | J12: 0.000521 | K12: 0.00032679
A13: 10743 | B13: 0.001871 | C13: 0.00117464 | D13: 0.00229 | E13: 0.00143733 | F13: 0.004905 | G13: 0.00307877 | H13: 0.00097 | I13: 0.00060887 | J13: 0.000401 | K13: 0.00025176
A14: 10798 | B14: 0.001953 | C14: 0.00122604 | D14: 0.003375 | E14: 0.00211831 | F14: 0.005174 | G14: 0.00324759 | H14: 0.003717 | I14: 0.00233315 | J14: 0.001363 | K14: 0.00085568
A15: 11039 | B15: 0.002099 | C15: 0.00131778 | D15: 0.003666 | E15: 0.00230123 | F15: 0.005786 | G15: 0.00363153 | H15: 0.002953 | I15: 0.00185367 | J15: 0.001106 | K15: 0.00069434
... A503: 9910 | B503: 0.001817 | C503: 0.00114034 | D503: 0.002584 | E503: 0.00162178 | F503: 0.005954 | G503: 0.00373723 | H503: 0.002331 | I503: 0.00146284 | J503: 0.001031 | K503: 0.00064731

Sheet Model_Configurations
A1: Five Model Configurations
A3: Configuration | B3: Phase 1 VLM | C3: Phases 2–5 LLM | D3: VLM Size | E3: LLM Size | F3: Raw Energy/Carbon Sheet
A4: Qwen | B4: Qwen/Qwen2-VL-7B-Instruct | C4: Qwen/Qwen2.5-7B-Instruct | D4: 7B | E4: 7B | F4: Qwen_Final
A5: Phi-3.5 | B5: microsoft/Phi-3.5-vision-instruct | C5: microsoft/Phi-3.5-mini-instruct | D5: ~4.2B | E5: 3.8B | F5: Phi_Final
A6: InternVL + InternLM | B6: OpenGVLab/InternVL2-8B | C6: internlm/internlm2_5-7b-chat | D6: 8B | E6: 7B | F6: InternVL_InternLM
A7: InternVL + Mistral | B7: OpenGVLab/InternVL2-8B | C7: mistralai/Mistral-7B-Instruct-v0.3 | D7: 8B | E7: 7B | F7: InternVL_Mistral
A8: InternVL + Llama-3 | B8: OpenGVLab/InternVL2-8B | C8: meta-llama/Meta-Llama-3.1-8B-Instruct | D8: 8B | E8: 8B | F8: InternVL_Llama

Sheet Phase1-3_Summary
A1: Phase 1–3 Completeness and MR Coverage (500 Screens)
A3: Configuration | B3: Phase 1 usable descriptions | C3: Phase 1 % | D3: Phase 2 screens with ≥1 TC | E3: Phase 2 % | F3: Total TCs | G3: Phase 3 screens with ≥1 MR | H3: MRC | I3: Total MRs | J3: Avg. MR categories/screen
A4: Qwen | B4: 498 | C4: =B4/500 -> 0.996 | D4: 498 | E4: =D4/500 -> 0.996 | F4: 4522 | G4: 495 | H4: =G4/500 -> 0.99 | I4: 2075 | J4: 1.558
A5: Phi-3.5 | B5: 468 | C5: =B5/500 -> 0.936 | D5: 471 | E5: =D5/500 -> 0.942 | F5: 2512 | G5: 458 | H5: =G5/500 -> 0.916 | I5: 1742 | J5: 1.66
A6: InternVL + InternLM | B6: 500 | C6: =B6/500 -> 1 | D6: 497 | E6: =D6/500 -> 0.994 | F6: 2833 | G6: 231 | H6: =G6/500 -> 0.462 | I6: 759 | J6: 0.706
A7: InternVL + Mistral | B7: 500 | C7: =B7/500 -> 1 | D7: 500 | E7: =D7/500 -> 1 | F7: 5788 | G7: 406 | H7: =G7/500 -> 0.812 | I7: 1417 | J7: 1.262
A8: InternVL + Llama-3 | B8: 500 | C8: =B8/500 -> 1 | D8: 500 | E8: =D8/500 -> 1 | F8: 4754 | G8: 490 | H8: =G8/500 -> 0.98 | I8: 2716 | J8: 2.122
A10: Qwen remains near-complete through Phase 3. Phi-3.5 shows moderate upstream loss. InternVL+InternLM has a major Phase-3 bottleneck; Mistral improves MRC to 81.2%, while Llama-3 raises it to 98.0%, close to Qwen.

Sheet Metric_Definitions
A1: Five Primary Metrics
A3: Metric | B3: Definition | C3: Formula used | D3: Excel implementation | E3: Evidence / caution
A4: Energy Consumption (EC) | B4: Measured generation energy across Phases 1–5. | C4: EC = Σ phase energy | D4: Per phase: =SUM(500 per-screen energy values); EC = SUM(Phase 1:Phase 5) | E4: Measured by CodeCarbon. Raw per-screen values are stored in the configuration sheets.
A5: Carbon Emissions (CE) | B5: Measured generation carbon across Phases 1–5. | C5: CE = Σ phase carbon | D5: Per phase: =SUM(500 per-screen carbon values); CE = SUM(Phase 1:Phase 5) | E5: Measured by CodeCarbon in kg CO2eq.
A6: MR Coverage (MRC) | B6: Share of 500 screens with ≥1 final MR. | C6: MRC = screens_with_MR / 500 | D6: SUM(0/1 MR flags) / 500 | E6: Proof sheet uses a 0/1 flag for each of the 500 screens.
A7: Deterministic Intervention Rate (DIR) | B7: Phase-5 share of checked scheduling proposals changed by deterministic clamping. | C7: DIR = clamped / checked | D7: SUM(Audited Clamped) / SUM(Checked Decisions) | E7: Phase-5 DIR: clamped proposals / checked model proposals. True fallbacks are excluded from the denominator and are identified only by explicit 'Fallback mapping ... LLM did not return an assignment' messages.
A8: Scheduling Savings Ratio (SSR) | B8: Projected recurring MR execution-energy saving after scheduling. | C8: SSR = (E_full-E_scheduled)/E_full | D8: (SUM(Unoptimized) - SUM(Optimized)) / SUM(Unoptimized) | E8: Projected execution cost, not CodeCarbon generation energy.

Sheet MR_Coverage_Proof
A1: MR Coverage Proof — Run 1 only: 1 = screen has ≥1 final Phase-3 MR; 0 = no final MR
A3: Screen ID | B3: Qwen | C3: Phi-3.5 | D3: InternVL + InternLM | E3: InternVL + Mistral | F3: InternVL + Llama-3
A4: 10214 | B4: 1 | C4: 1 | D4: 1 | E4: 1 | F4: 1
A5: 1028 | B5: 1 | C5: 1 | D5: 1 | E5: 1 | F5: 1
A6: 10440 | B6: 1 | C6: 1 | D6: 1 | E6: 1 | F6: 1
A7: 10498 | B7: 1 | C7: 0 | D7: 0 | E7: 1 | F7: 1
A8: 10538 | B8: 1 | C8: 0 | D8: 0 | E8: 1 | F8: 1
A9: 10592 | B9: 1 | C9: 1 | D9: 1 | E9: 1 | F9: 1
A10: 10612 | B10: 1 | C10: 1 | D10: 1 | E10: 1 | F10: 1
A11: 10636 | B11: 1 | C11: 1 | D11: 1 | E11: 1 | F11: 1
A12: 1074 | B12: 1 | C12: 1 | D12: 1 | E12: 1 | F12: 1
A13: 10743 | B13: 1 | C13: 1 | D13: 0 | E13: 1 | F13: 1
A14: 10798 | B14: 1 | C14: 1 | D14: 0 | E14: 1 | F14: 1
A15: 11039 | B15: 1 | C15: 1 | D15: 0 | E15: 0 | F15: 1
... A503: 9910 | B503: 1 | C503: 1 | D503: 0 | E503: 1 | F503: 1
A504: Screens with ≥1 MR | B504: =SUM(B4:B503) -> 495 | C504: =SUM(C4:C503) -> 458 | D504: =SUM(D4:D503) -> 231 | E504: =SUM(E4:E503) -> 406 | F504: =SUM(F4:F503) -> 490
A505: MRC | B505: =B504/500 -> 0.99 | C505: =C504/500 -> 0.916 | D505: =D504/500 -> 0.462 | E505: =E504/500 -> 0.812 | F505: =F504/500 -> 0.98

Sheet Phase5_Raw
A1: Phase-5 Scheduling Evidence — primary DIR and SSR calculations use Run 1 only
A3: Configuration | B3: Run | C3: Screen ID | D3: Total MRs | E3: Summary LLM tier count | F3: Summary clamped count | G3: Summary fallback count | H3: Audited clamped (reasoning) | I3: Audited fallback (reasoning) | J3: Checked decisions | K3: Unoptimized kWh/cycle | L3: Optimized kWh/cycle | M3: Screen SSR | N3: Audit note
A4: InternVL + Mistral | B4: 1 | C4: 10214 | D4: 6 | E4: 1 | F4: 5 | G4: 0 | H4: 5 | I4: 0 | J4: 6 | K4: 0.003 | L4: 0.0005 | M4: 0.83333333
A5: InternVL + Mistral | B5: 1 | C5: 1028 | D5: 3 | E5: 3 | F5: 0 | G5: 0 | H5: 0 | I5: 0 | J5: 3 | K5: 0.0015 | L5: 0.00075 | M5: 0.5
A6: InternVL + Mistral | B6: 1 | C6: 10440 | D6: 1 | E6: 1 | F6: 0 | G6: 0 | H6: 0 | I6: 0 | J6: 1 | K6: 0.0005 | L6: 0.0005 | M6: 0
A7: InternVL + Mistral | B7: 1 | C7: 10498 | D7: 5 | E7: 4 | F7: 1 | G7: 0 | H7: 1 | I7: 0 | J7: 5 | K7: 0.0025 | L7: 0.0005 | M7: 0.8
A8: InternVL + Mistral | B8: 1 | C8: 10538 | D8: 5 | E8: 5 | F8: 0 | G8: 0 | H8: 0 | I8: 0 | J8: 5 | K8: 0.0025 | L8: 0.001 | M8: 0.6
A9: InternVL + Mistral | B9: 1 | C9: 10592 | D9: 7 | E9: 4 | F9: 3 | G9: 0 | H9: 3 | I9: 0 | J9: 7 | K9: 0.0035 | L9: 0.002 | M9: 0.42857143
A10: InternVL + Mistral | B10: 1 | C10: 10612 | D10: 5 | E10: 5 | F10: 0 | G10: 0 | H10: 0 | I10: 0 | J10: 5 | K10: 0.0025 | L10: 0.00125 | M10: 0.5
A11: InternVL + Mistral | B11: 1 | C11: 10636 | D11: 2 | E11: 2 | F11: 0 | G11: 0 | H11: 0 | I11: 0 | J11: 2 | K11: 0.001 | L11: 0.0005 | M11: 0.5
A12: InternVL + Mistral | B12: 1 | C12: 1074 | D12: 7 | E12: 6 | F12: 1 | G12: 0 | H12: 1 | I12: 0 | J12: 7 | K12: 0.0035 | L12: 0.00225 | M12: 0.35714286
A13: InternVL + Mistral | B13: 1 | C13: 10743 | D13: 2 | E13: 1 | F13: 1 | G13: 0 | H13: 1 | I13: 0 | J13: 2 | K13: 0.001 | L13: 0.0005 | M13: 0.5
A14: InternVL + Mistral | B14: 1 | C14: 10798 | D14: 1 | E14: 1 | F14: 0 | G14: 0 | H14: 0 | I14: 0 | J14: 1 | K14: 0.0005 | L14: 0.0005 | M14: 0
A15: InternVL + Mistral | B15: 1 | C15: 11039 | D15: 0 | E15: 0 | F15: 0 | G15: 0 | H15: 0 | I15: 0 | J15: 0 | K15: 0 | L15: 0
A16: InternVL + Mistral | B16: 1 | C16: 1115 | D16: 0 | E16: 0 | F16: 0 | G16: 0 | H16: 0 | I16: 0 | J16: 0 | K16: 0 | L16: 0
A17: InternVL + Mistral | B17: 1 | C17: 11233 | D17: 9 | E17: 8 | F17: 1 | G17: 0 | H17: 1 | I17: 0 | J17: 9 | K17: 0.0045 | L17: 0.00275 | M17: 0.38888889
A18: InternVL + Mistral | B18: 1 | C18: 11347 | D18: 2 | E18: 1 | F18: 1 | G18: 0 | H18: 1 | I18: 0 | J18: 2 | K18: 0.001 | L18: 0.0005 | M18: 0.5
A19: InternVL + Mistral | B19: 1 | C19: 11393 | D19: 1 | E19: 1 | F19: 0 | G19: 0 | H19: 0 | I19: 0 | J19: 1 | K19: 0.0005 | L19: 0.0005 | M19: 0
A20: InternVL + Mistral | B20: 1 | C20: 11475 | D20: 0 | E20: 0 | F20: 0 | G20: 0 | H20: 0 | I20: 0 | J20: 0 | K20: 0 | L20: 0
A21: InternVL + Mistral | B21: 1 | C21: 11746 | D21: 2 | E21: 2 | F21: 0 | G21: 0 | H21: 0 | I21: 0 | J21: 2 | K21: 0.001 | L21: 0.00075 | M21: 0.25
A22: InternVL + Mistral | B22: 1 | C22: 11794 | D22: 2 | E22: 1 | F22: 1 | G22: 0 | H22: 1 | I22: 0 | J22: 2 | K22: 0.001 | L22: 0.0005 | M22: 0.5
A23: InternVL + Mistral | B23: 1 | C23: 1184 | D23: 0 | E23: 0 | F23: 0 | G23: 0 | H23: 0 | I23: 0 | J23: 0 | K23: 0 | L23: 0
A24: InternVL + Mistral | B24: 1 | C24: 12176 | D24: 0 | E24: 0 | F24: 0 | G24: 0 | H24: 0 | I24: 0 | J24: 0 | K24: 0 | L24: 0
A25: InternVL + Mistral | B25: 1 | C25: 12188 | D25: 2 | E25: 1 | F25: 1 | G25: 0 | H25: 1 | I25: 0 | J25: 2 | K25: 0.001 | L25: 0.0005 | M25: 0.5
A26: InternVL + Mistral | B26: 1 | C26: 12393 | D26: 3 | E26: 3 | F26: 0 | G26: 0 | H26: 0 | I26: 0 | J26: 3 | K26: 0.0015 | L26: 0.001 | M26: 0.33333333
A27: InternVL + Mistral | B27: 1 | C27: 12449 | D27: 2 | E27: 1 | F27: 1 | G27: 0 | H27: 1 | I27: 0 | J27: 2 | K27: 0.001 | L27: 0.0005 | M27: 0.5
A28: InternVL + Mistral | B28: 1 | C28: 12581 | D28: 1 | E28: 1 | F28: 0 | G28: 0 | H28: 0 | I28: 0 | J28: 1 | K28: 0.0005 | L28: 0.0005 | M28: 0
A29: InternVL + Mistral | B29: 1 | C29: 12921 | D29: 1 | E29: 1 | F29: 0 | G29: 0 | H29: 0 | I29: 0 | J29: 1 | K29: 0.0005 | L29: 0.0005 | M29: 0
A30: InternVL + Mistral | B30: 1 | C30: 12952 | D30: 3 | E30: 1 | F30: 2 | G30: 0 | H30: 2 | I30: 0 | J30: 3 | K30: 0.0015 | L30: 0.0005 | M30: 0.66666667
A31: InternVL + Mistral | B31: 1 | C31: 13189 | D31: 0 | E31: 0 | F31: 0 | G31: 0 | H31: 0 | I31: 0 | J31: 0 | K31: 0 | L31: 0
A32: InternVL + Mistral | B32: 1 | C32: 1332 | D32: 4 | E32: 2 | F32: 2 | G32: 0 | H32: 2 | I32: 0 | J32: 4 | K32: 0.002 | L32: 0.00075 | M32: 0.625
A33: InternVL + Mistral | B33: 1 | C33: 13410 | D33: 0 | E33: 0 | F33: 0 | G33: 0 | H33: 0 | I33: 0 | J33: 0 | K33: 0 | L33: 0
A34: InternVL + Mistral | B34: 1 | C34: 13575 | D34: 2 | E34: 2 | F34: 0 | G34: 0 | H34: 0 | I34: 0 | J34: 2 | K34: 0.001 | L34: 0.00075 | M34: 0.25
A35: InternVL + Mistral | B35: 1 | C35: 13705 | D35: 2 | E35: 2 | F35: 0 | G35: 0 | H35: 0 | I35: 0 | J35: 2 | K35: 0.001 | L35: 0.00075 | M35: 0.25
A36: InternVL + Mistral | B36: 1 | C36: 13829 | D36: 2 | E36: 1 | F36: 1 | G36: 0 | H36: 1 | I36: 0 | J36: 2 | K36: 0.001 | L36: 0.0005 | M36: 0.5
A37: InternVL + Mistral | B37: 1 | C37: 14085 | D37: 7 | E37: 7 | F37: 0 | G37: 0 | H37: 0 | I37: 0 | J37: 7 | K37: 0.0035 | L37: 0.00125 | M37: 0.64285714
A38: InternVL + Mistral | B38: 1 | C38: 14247 | D38: 6 | E38: 2 | F38: 4 | G38: 0 | H38: 4 | I38: 0 | J38: 6 | K38: 0.003 | L38: 0.001 | M38: 0.66666667
A39: InternVL + Mistral | B39: 1 | C39: 14307 | D39: 1 | E39: 1 | F39: 0 | G39: 0 | H39: 0 | I39: 0 | J39: 1 | K39: 0.0005 | L39: 0.0005 | M39: 0
A40: InternVL + Mistral | B40: 1 | C40: 14549 | D40: 7 | E40: 7 | F40: 0 | G40: 0 | H40: 0 | I40: 0 | J40: 7 | K40: 0.0035 | L40: 0.001 | M40: 0.71428571
A41: InternVL + Mistral | B41: 1 | C41: 1460 | D41: 1 | E41: 1 | F41: 0 | G41: 0 | H41: 0 | I41: 0 | J41: 1 | K41: 0.0005 | L41: 0.0005 | M41: 0
...

Sheet Metrics_Calculation
A1: Five-Metric Calculations
A3: Configuration | B3: Run | C3: P1 Energy | D3: P2 Energy | E3: P3 Energy | F3: P4 Energy | G3: P5 Energy | H3: EC Total (kWh) | I3: P1 Carbon | J3: P2 Carbon | K3: P3 Carbon | L3: P4 Carbon | M3: P5 Carbon | N3: CE Total (kg CO2eq) | O3: Screens with MR | P3: Total Screens | Q3: MRC | R3: Audited Clamped | S3: Audited Fallback | T3: Checked Decisions | U3: Phase-5 DIR | V3: Full Exec kWh/cycle | W3: Scheduled kWh/cycle | X3: SSR | Y3: Notes
A4: Qwen | B4: 1 | C4: =SUM(Qwen_Final!B4:B503) -> 0.798075 | D4: =SUM(Qwen_Final!D4:D503) -> 1.680026 | E4: =SUM(Qwen_Final!F4:F503) -> 1.438091 | F4: =SUM(Qwen_Final!H4:H503) -> 0.960636 | G4: =SUM(Qwen_Final!J4:J503) -> 0.369737 | H4: =SUM(C4:G4) -> 5.246565 | I4: =SUM(Qwen_Final!C4:C503) -> 0.50092295 | J4: =SUM(Qwen_Final!E4:E503) -> 1.054511 | K4: =SUM(Qwen_Final!G4:G503) -> 0.9026562 | L4: =SUM(Qwen_Final!I4:I503) -> 0.60296798 | M4: =SUM(Qwen_Final!K4:K503) -> 0.23207049 | N4: =SUM(I4:M4) -> 3.2931287 | O4: =SUM(MR_Coverage_Proof!B4:B503) -> 495 | P4: 500 | Q4: =O4/P4 -> 0.99 | R4: =SUMIFS(Phase5_Raw!$H$4:$H$3503,Phase5_Raw!$A$4:$A$3503,$A4,Phase5_Raw!$B$4:$B$3503,$B4) -> 873 | S4: =SUMIFS(Phase5_Raw!$I$4:$I$3503,Phase5_Raw!$A$4:$A$3503,$A4,Phase5_Raw!$B$4:$B$3503,$B4) -> 1 | T4: =SUMIFS(Phase5_Raw!$J$4:$J$3503,Phase5_Raw!$A$4:$A$3503,$A4,Phase5_Raw!$B$4:$B$3503,$B4) -> 2031 | U4: =IF(T4=0,"",R4/T4) -> 0.42983752 | V4: =SUMIFS(Phase5_Raw!$K$4:$K$3503,Phase5_Raw!$A$4:$A$3503,$A4,Phase5_Raw!$B$4:$B$3503,$B4) -> 1.016 | W4: =SUMIFS(Phase5_Raw!$L$4:$L$3503,Phase5_Raw!$A$4:$A$3503,$A4,Phase5_Raw!$B$4:$B$3503,$B4) -> 0.46102508 | X4: =IF(V4=0,"",(V4-W4)/V4) -> 0.54623516 | Y4: All five primary metrics are populated.
A5: Phi-3.5 | B5: 1 | C5: =SUM(Phi_Final!B4:B503) -> 0.891295 | D5: =SUM(Phi_Final!D4:D503) -> 1.49123 | E5: =SUM(Phi_Final!F4:F503) -> 1.871711 | F5: =SUM(Phi_Final!H4:H503) -> 0.793418 | G5: =SUM(Phi_Final!J4:J503) -> 0.449996 | H5: =SUM(C5:G5) -> 5.49765 | I5: =SUM(Phi_Final!C4:C503) -> 0.55943733 | J5: =SUM(Phi_Final!E4:E503) -> 0.9360012 | K5: =SUM(Phi_Final!G4:G503) -> 1.1748204 | L5: =SUM(Phi_Final!I4:I503) -> 0.49800576 | M5: =SUM(Phi_Final!K4:K503) -> 0.28245004 | N5: =SUM(I5:M5) -> 3.4507147 | O5: =SUM(MR_Coverage_Proof!C4:C503) -> 458 | P5: 500 | Q5: =O5/P5 -> 0.916 | R5: =SUMIFS(Phase5_Raw!$H$4:$H$3503,Phase5_Raw!$A$4:$A$3503,$A5,Phase5_Raw!$B$4:$B$3503,$B5) -> 365 | S5: =SUMIFS(Phase5_Raw!$I$4:$I$3503,Phase5_Raw!$A$4:$A$3503,$A5,Phase5_Raw!$B$4:$B$3503,$B5) -> 21 | T5: =SUMIFS(Phase5_Raw!$J$4:$J$3503,Phase5_Raw!$A$4:$A$3503,$A5,Phase5_Raw!$B$4:$B$3503,$B5) -> 1721 | U5: =IF(T5=0,"",R5/T5) -> 0.212086 | V5: =SUMIFS(Phase5_Raw!$K$4:$K$3503,Phase5_Raw!$A$4:$A$3503,$A5,Phase5_Raw!$B$4:$B$3503,$B5) -> 0.871 | W5: =SUMIFS(Phase5_Raw!$L$4:$L$3503,Phase5_Raw!$A$4:$A$3503,$A5,Phase5_Raw!$B$4:$B$3503,$B5) -> 0.60776848 | X5: =IF(V5=0,"",(V5-W5)/V5) -> 0.30221759 | Y5: Phase-5 audit uses detailed reasoning evidence.
A6: InternVL + InternLM | B6: 1 | C6: =SUM(InternVL_InternLM!B4:B503) -> 0.860497 | D6: =SUM(InternVL_InternLM!D4:D503) -> 2.684219 | E6: =SUM(InternVL_InternLM!F4:F503) -> 2.174899 | F6: =SUM(InternVL_InternLM!H4:H503) -> 0.401366 | G6: =SUM(InternVL_InternLM!J4:J503) -> 0.207613 | H6: =SUM(C6:G6) -> 6.328594 | I6: =SUM(InternVL_InternLM!C4:C503) -> 0.54011126 | J6: =SUM(InternVL_InternLM!E4:E503) -> 1.6848254 | K6: =SUM(InternVL_InternLM!G4:G503) -> 1.3651245 | L6: =SUM(InternVL_InternLM!I4:I503) -> 0.25193231 | M6: =SUM(InternVL_InternLM!K4:K503) -> 0.13030595 | N6: =SUM(I6:M6) -> 3.9722994 | O6: =SUM(MR_Coverage_Proof!D4:D503) -> 231 | P6: 500 | Q6: =O6/P6 -> 0.462 | R6: =SUMIFS(Phase5_Raw!$H$4:$H$3503,Phase5_Raw!$A$4:$A$3503,$A6,Phase5_Raw!$B$4:$B$3503,$B6) -> 175 | S6: =SUMIFS(Phase5_Raw!$I$4:$I$3503,Phase5_Raw!$A$4:$A$3503,$A6,Phase5_Raw!$B$4:$B$3503,$B6) -> 18 | T6: =SUMIFS(Phase5_Raw!$J$4:$J$3503,Phase5_Raw!$A$4:$A$3503,$A6,Phase5_Raw!$B$4:$B$3503,$B6) -> 927 | U6: =IF(T6=0,"",R6/T6) -> 0.18878101 | V6: =SUMIFS(Phase5_Raw!$K$4:$K$3503,Phase5_Raw!$A$4:$A$3503,$A6,Phase5_Raw!$B$4:$B$3503,$B6) -> 0.4725 | W6: =SUMIFS(Phase5_Raw!$L$4:$L$3503,Phase5_Raw!$A$4:$A$3503,$A6,Phase5_Raw!$B$4:$B$3503,$B6) -> 0.29703335 | X6: =IF(V6=0,"",(V6-W6)/V6) -> 0.37135799 | Y6: DIR uses 18 true deterministic fallbacks identified from explicit fallback-mapping messages.
A7: InternVL + Mistral | B7: 1 | C7: =SUM(InternVL_Mistral!B4:B503) -> 0.882643 | D7: =SUM(InternVL_Mistral!D4:D503) -> 2.555117 | E7: =SUM(InternVL_Mistral!F4:F503) -> 1.263708 | F7: =SUM(InternVL_Mistral!H4:H503) -> 0.552332 | G7: =SUM(InternVL_Mistral!J4:J503) -> 0.303854 | H7: =SUM(C7:G7) -> 5.557654 | I7: =SUM(InternVL_Mistral!C4:C503) -> 0.55400643 | J7: =SUM(InternVL_Mistral!E4:E503) -> 1.6037778 | K7: =SUM(InternVL_Mistral!G4:G503) -> 0.79319067 | L7: =SUM(InternVL_Mistral!I4:I503) -> 0.3466866 | M7: =SUM(InternVL_Mistral!K4:K503) -> 0.19073314 | N7: =SUM(I7:M7) -> 3.4883947 | O7: =SUM(MR_Coverage_Proof!E4:E503) -> 406 | P7: 500 | Q7: =O7/P7 -> 0.812 | R7: =SUMIFS(Phase5_Raw!$H$4:$H$3503,Phase5_Raw!$A$4:$A$3503,$A7,Phase5_Raw!$B$4:$B$3503,$B7) -> 233 | S7: =SUMIFS(Phase5_Raw!$I$4:$I$3503,Phase5_Raw!$A$4:$A$3503,$A7,Phase5_Raw!$B$4:$B$3503,$B7) -> 22 | T7: =SUMIFS(Phase5_Raw!$J$4:$J$3503,Phase5_Raw!$A$4:$A$3503,$A7,Phase5_Raw!$B$4:$B$3503,$B7) -> 1395 | U7: =IF(T7=0,"",R7/T7) -> 0.16702509 | V7: =SUMIFS(Phase5_Raw!$K$4:$K$3503,Phase5_Raw!$A$4:$A$3503,$A7,Phase5_Raw!$B$4:$B$3503,$B7) -> 0.7085 | W7: =SUMIFS(Phase5_Raw!$L$4:$L$3503,Phase5_Raw!$A$4:$A$3503,$A7,Phase5_Raw!$B$4:$B$3503,$B7) -> 0.3589834 | X7: =IF(V7=0,"",(V7-W7)/V7) -> 0.49331912 | Y7: All five primary metrics are populated.
A8: InternVL + Llama-3 | B8: 1 | C8: =SUM(InternVL_Llama!B4:B503) -> 0.906948 | D8: =SUM(InternVL_Llama!D4:D503) -> 1.447113 | E8: =SUM(InternVL_Llama!F4:F503) -> 3.259608 | F8: =SUM(InternVL_Llama!H4:H503) -> 0.99337 | G8: =SUM(InternVL_Llama!J4:J503) -> 0.442759 | H8: =SUM(C8:G8) -> 7.049798 | I8: =SUM(InternVL_Llama!C4:C503) -> 0.56926453 | J8: =SUM(InternVL_Llama!E4:E503) -> 0.90831225 | K8: =SUM(InternVL_Llama!G4:G503) -> 2.0459734 | L8: =SUM(InternVL_Llama!I4:I503) -> 0.62351007 | M8: =SUM(InternVL_Llama!K4:K503) -> 0.27791476 | N8: =SUM(I8:M8) -> 4.424975 | O8: =SUM(MR_Coverage_Proof!F4:F503) -> 490 | P8: 500 | Q8: =O8/P8 -> 0.98 | R8: =SUMIFS(Phase5_Raw!$H$4:$H$3503,Phase5_Raw!$A$4:$A$3503,$A8,Phase5_Raw!$B$4:$B$3503,$B8) -> 10 | S8: =SUMIFS(Phase5_Raw!$I$4:$I$3503,Phase5_Raw!$A$4:$A$3503,$A8,Phase5_Raw!$B$4:$B$3503,$B8) -> 1 | T8: =SUMIFS(Phase5_Raw!$J$4:$J$3503,Phase5_Raw!$A$4:$A$3503,$A8,Phase5_Raw!$B$4:$B$3503,$B8) -> 2715 | U8: =IF(T8=0,"",R8/T8) -> 0.0036832413 | V8: =SUMIFS(Phase5_Raw!$K$4:$K$3503,Phase5_Raw!$A$4:$A$3503,$A8,Phase5_Raw!$B$4:$B$3503,$B8) -> 1.358 | W8: =SUMIFS(Phase5_Raw!$L$4:$L$3503,Phase5_Raw!$A$4:$A$3503,$A8,Phase5_Raw!$B$4:$B$3503,$B8) -> 0.72337223 | X8: =IF(V8=0,"",(V8-W8)/V8) -> 0.46732531 | Y8: All five primary metrics are populated.

Sheet Repeatability_Check_QWEN
A1: Screen ID | B1: Phase 1 – UI Perception | H1: Phase 2 – Source Test Generation | N1: Phase 3 – MR Generation | T1: Phase 4 – MR Prioritization | Z1: Phase 5 – Execution Scheduling
B2: Energy (kWh) | E2: Carbon Emissions (kg CO₂eq) | H2: Energy (kWh) | K2: Carbon Emissions (kg CO₂eq) | N2: Energy (kWh) | Q2: Carbon Emissions (kg CO₂eq) | T2: Energy (kWh) | W2: Carbon Emissions (kg CO₂eq) | Z2: Energy (kWh) | AC2: Carbon Emissions (kg CO₂eq)
B3: Run 1 | C3: Run 2 | D3: Run 3 | E3: Run 1 | F3: Run 2 | G3: Run 3 | H3: Run 1 | I3: Run 2 | J3: Run 3 | K3: Run 1 | L3: Run 2 | M3: Run 3 | N3: Run 1 | O3: Run 2 | P3: Run 3 | Q3: Run 1 | R3: Run 2 | S3: Run 3 | T3: Run 1 | U3: Run 2 | V3: Run 3 | W3: Run 1 | X3: Run 2 | Y3: Run 3 | Z3: Run 1 | AA3: Run 2 | AB3: Run 3 | AC3: Run 1 | AD3: Run 2 | AE3: Run 3
A4: 10214 | B4: 0.001209 | C4: 0.00134 | D4: 0.001264 | E4: 0.00075902 | F4: 0.0008408 | G4: 0.00079363 | H4: 0.000659 | I4: 0.00066 | J4: 0.000725 | K4: 0.00041376 | L4: 0.00041413 | M4: 0.00045538 | N4: 0.000887 | O4: 0.000988 | P4: 0.000864 | Q4: 0.0005567 | R4: 0.00062014 | S4: 0.00054226 | T4: 0.000922 | U4: 0.000903 | V4: 0.000971 | W4: 0.00057865 | X4: 0.00056668 | Y4: 0.00060923 | Z4: 0.000397 | AA4: 0.000399 | AB4: 0.000404 | AC4: 0.00024912 | AD4: 0.00025035 | AE4: 0.00025375
A5: 1028 | B5: 0.001745 | C5: 0.0018 | D5: 0.001879 | E5: =MAX(B5:D5)-MIN(B5:D5) -> 0.000134 | F5: 0.00112968 | G5: 0.00117969 | H5: 0.007941 | I5: =MAX(F5:H5)-MIN(F5:H5) -> 0.00681132 | J5: 0.007534 | K5: 0.00498461 | L5: 0.00478172 | M5: 0.00472876 | N5: 0.004421 | O5: 0.004467 | P5: 0.004445 | Q5: 0.00277465 | R5: 0.00280394 | S5: 0.00278977 | T5: 0.006766 | U5: 0.006835 | V5: 0.006927 | W5: 0.0042468 | X5: 0.00428989 | Y5: 0.0043482 | Z5: 0.002236 | AA5: 0.002049 | AB5: 0.002077 | AC5: 0.0014035 | AD5: 0.00128627 | AE5: 0.00130399
A6: 10440 | B6: 0.001265 | C6: 0.001262 | D6: 0.001238 | E6: =MAX(B6:D6)-MIN(B6:D6) -> 2.7e-05 | F6: 0.000792 | G6: 0.0007768 | H6: 0.004514 | I6: =MAX(F6:H6)-MIN(F6:H6) -> 0.0037372 | J6: 0.004548 | K6: 0.00283302 | L6: 0.00296492 | M6: 0.00285483 | N6: 0.002834 | O6: 0.002653 | P6: 0.002766 | Q6: 0.00177906 | R6: 0.00166552 | S6: 0.00173624 | T6: 0.006129 | U6: 0.005911 | V6: 0.005941 | W6: 0.00384732 | X6: 0.00371043 | Y6: 0.00372901 | Z6: 0.001971 | AA6: 0.001983 | AB6: 0.00209 | AC6: 0.00123726 | AD6: 0.00124466 | AE6: 0.00131165
A7: 10498 | B7: 0.001375 | C7: 0.00146 | D7: 0.001252 | E7: =MAX(B7:D7)-MIN(B7:D7) -> 0.000208 | F7: 0.00091632 | G7: 0.00078602 | H7: 0.002549 | I7: =MAX(F7:H7)-MIN(F7:H7) -> 0.00176298 | J7: 0.002457 | K7: 0.00159981 | L7: 0.00153661 | M7: 0.00154242 | N7: 0.002107 | O7: 0.00224 | P7: 0.002152 | Q7: 0.0013226 | R7: 0.00140585 | S7: 0.00135101 | T7: 0.003289 | U7: 0.003095 | V7: 0.00314 | W7: 0.00206459 | X7: 0.00194286 | Y7: 0.00197086 | Z7: 0.001088 | AA7: 0.001144 | AB7: 0.001099 | AC7: 0.00068289 | AD7: 0.00071788 | AE7: 0.00069006
A8: 10538 | B8: 0.001702 | C8: 0.001711 | D8: 0.001632 | E8: 0.00106813 | F8: 0.00107376 | G8: 0.00102432 | H8: 0.004157 | I8: 0.004103 | J8: 0.004434 | K8: 0.00260926 | L8: 0.00257516 | M8: 0.00278337 | N8: 0.005032 | O8: 0.005032 | P8: 0.005015 | Q8: 0.0031587 | R8: 0.00315837 | S8: 0.00314754 | T8: 0.001383 | U8: 0.001461 | V8: 0.001401 | W8: 0.00086804 | X8: 0.00091705 | Y8: 0.00087932 | Z8: 0.000583 | AA8: 0.000564 | AB8: 0.000588 | AC8: 0.00036617 | AD8: 0.00035432 | AE8: 0.00036883
A9: 10592 | B9: 0.001339 | C9: 0.001372 | D9: 0.001327 | E9: 0.00084043 | F9: 0.00086126 | G9: 0.0008329 | H9: 0.001184 | I9: 0.001232 | J9: 0.001228 | K9: 0.00074326 | L9: 0.00077344 | M9: 0.00077086 | N9: 0.001787 | O9: 0.00181 | P9: 0.001802 | Q9: 0.00112177 | R9: 0.00113608 | S9: 0.00113111 | T9: 0.002283 | U9: 0.002347 | V9: 0.002413 | W9: 0.00143271 | X9: 0.00147332 | Y9: 0.00151462 | Z9: 0.000893 | AA9: 0.00081 | AB9: 0.000903 | AC9: 0.00056063 | AD9: 0.00050864 | AE9: 0.00056701
A10: 10612 | B10: 0.002026 | C10: 0.001999 | D10: 0.001986 | E10: 0.0012717 | F10: 0.0012545 | G10: 0.00124685 | H10: 0.004405 | I10: 0.004271 | J10: 0.004152 | K10: 0.00276466 | L10: 0.00268102 | M10: 0.00260609 | N10: 0.003584 | O10: 0.003587 | P10: 0.003527 | Q10: 0.00224963 | R10: 0.00225128 | S10: 0.00221406 | T10: 0.004077 | U10: 0.004026 | V10: 0.003943 | W10: 0.00255931 | X10: 0.00252699 | Y10: 0.00247521 | Z10: 0.001587 | AA10: 0.001507 | AB10: 0.001534 | AC10: 0.00099594 | AD10: 0.00094597 | AE10: 0.00096312
A11: 10636 | B11: 0.001675 | C11: 0.00169 | D11: 0.001579 | E11: 0.00105158 | F11: 0.00106052 | G11: 0.00099092 | H11: 0.003716 | I11: 0.003613 | J11: 0.003521 | K11: 0.00233246 | L11: 0.00226801 | M11: 0.0022103 | N11: 0.002316 | O11: 0.00224 | P11: 0.002168 | Q11: 0.0014538 | R11: 0.00140596 | S11: 0.00136061 | T11: 0.004693 | U11: 0.004622 | V11: 0.004559 | W11: 0.00294554 | X11: 0.00290124 | Y11: 0.00286136 | Z11: 0.00164 | AA11: 0.001545 | AB11: 0.001547 | AC11: 0.00102963 | AD11: 0.00096951 | AE11: 0.00097071
A12: 1074 | B12: 0.001555 | C12: 0.001552 | D12: 0.0015 | E12: 0.00097615 | F12: 0.00097391 | G12: 0.0009418 | H12: 0.003765 | I12: 0.003709 | J12: 0.003682 | K12: 0.00236327 | L12: 0.00232821 | M12: 0.00231099 | N12: 0.002253 | O12: 0.00224 | P12: 0.002172 | Q12: 0.00141424 | R12: 0.00140629 | S12: 0.0013634 | T12: 0.001933 | U12: 0.001812 | V12: 0.001849 | W12: 0.00121326 | X12: 0.00113709 | Y12: 0.00116065 | Z12: 0.000798 | AA12: 0.000669 | AB12: 0.000751 | AC12: 0.00050119 | AD12: 0.00042017 | AE12: 0.00047107
A13: 10743 | B13: 0.00154 | C13: 0.00146 | D13: 0.001542 | E13: 0.00096672 | F13: 0.00091634 | G13: 0.00096798 | H13: 0.004628 | I13: 0.004437 | J13: 0.004326 | K13: 0.002905 | L13: 0.00278468 | M13: 0.00271528 | N13: 0.002641 | O13: 0.002522 | P13: 0.002526 | Q13: 0.00165747 | R13: 0.00158286 | S13: 0.0015853 | T13: 0.001081 | U13: 0.000923 | V13: 0.001035 | W13: 0.00067843 | X13: 0.00057938 | Y13: 0.00064957 | Z13: 0.000476 | AA13: 0.000411 | AB13: 0.000419 | AC13: 0.00029884 | AD13: 0.00025784 | AE13: 0.00026289
A14: 10798 | B14: 0.001588 | C14: 0.001481 | D14: 0.001546 | E14: 0.00099681 | F14: 0.00092939 | G14: 0.00097037 | H14: 0.00589 | I14: 0.005666 | J14: 0.005738 | K14: 0.00369703 | L14: 0.00355661 | M14: 0.00360182 | N14: 0.005187 | O14: 0.005252 | P14: 0.005187 | Q14: 0.00325557 | R14: 0.00329657 | S14: 0.00325558 | T14: 0.003962 | U14: 0.004061 | V14: 0.003841 | W14: 0.00248694 | X14: 0.00254914 | Y14: 0.00241064 | Z14: 0.001576 | AA14: 0.001428 | AB14: 0.001535 | AC14: 0.00098924 | AD14: 0.00089649 | AE14: 0.0009636
A15: 11039 | B15: 0.00168 | C15: 0.001558 | D15: 0.0016 | E15: 0.00105455 | F15: 0.00097815 | G15: 0.00100439 | H15: 0.003142 | I15: 0.003101 | J15: 0.003021 | K15: 0.00197208 | L15: 0.00194651 | M15: 0.00189599 | N15: 0.003098 | O15: 0.003031 | P15: 0.003037 | Q15: 0.00194437 | R15: 0.00190255 | S15: 0.00190602 | T15: 0.002989 | U15: 0.003059 | V15: 0.003244 | W15: 0.00187629 | X15: 0.00191982 | Y15: 0.00203604 | Z15: 0.001153 | AA15: 0.001015 | AB15: 0.001012 | AC15: 0.00072388 | AD15: 0.00063679 | AE15: 0.00063494
A16: 1115 | B16: 0.001794 | C16: 0.001721 | D16: 0.001656 | E16: 0.00112592 | F16: 0.00108047 | G16: 0.00103947 | H16: 0.00108 | I16: 0.000987 | J16: 0.001042 | K16: 0.00067781 | L16: 0.00061925 | M16: 0.00065378 | N16: 0.001321 | O16: 0.001382 | P16: 0.00139 | Q16: 0.0008293 | R16: 0.00086742 | S16: 0.00087272 | T16: 0.001427 | U16: 0.001325 | V16: 0.001274 | W16: 0.00089557 | X16: 0.0008317 | Y16: 0.00079972 | Z16: 0.000582 | AA16: 0.00048 | AB16: 0.000551 | AC16: 0.00036529 | AD16: 0.00030121 | AE16: 0.00034567
A17: 11233 | B17: 0.001898 | C17: 0.001795 | D17: 0.001788 | E17: 0.00119122 | F17: 0.00112672 | G17: 0.00112203 | H17: 0.003744 | I17: 0.003597 | J17: 0.003686 | K17: 0.00234985 | L17: 0.00225797 | M17: 0.00231342 | N17: 0.001136 | O17: 0.001155 | P17: 0.00112 | Q17: 0.00071323 | R17: 0.00072467 | S17: 0.00070281 | T17: 0.000987 | U17: 0.000938 | V17: 0.000935 | W17: 0.00061982 | X17: 0.00058889 | Y17: 0.000587 | Z17: 0.000417 | AA17: 0.000397 | AB17: 0.000408 | AC17: 0.00026174 | AD17: 0.00024948 | AE17: 0.0002564
A18: 11347 | B18: 0.001345 | C18: 0.001264 | D18: 0.001293 | E18: 0.00084408 | F18: 0.00079321 | G18: 0.00081172 | H18: 0.001393 | I18: 0.001357 | J18: 0.001352 | K18: 0.00087461 | L18: 0.00085175 | M18: 0.00084834 | N18: 0.001611 | O18: 0.0015 | P18: 0.001508 | Q18: 0.00101146 | R18: 0.00094176 | S18: 0.00094676 | T18: 0.002125 | U18: 0.002105 | V18: 0.002117 | W18: 0.0013336 | X18: 0.00132141 | Y18: 0.00132889 | Z18: 0.000602 | AA18: 0.000544 | AB18: 0.00052 | AC18: 0.00037791 | AD18: 0.00034125 | AE18: 0.00032631
A19: 11393 | B19: 0.001688 | C19: 0.001662 | D19: 0.001592 | E19: 0.0010595 | F19: 0.00104348 | G19: 0.00099922 | H19: 0.001881 | I19: 0.001794 | J19: 0.001803 | K19: 0.00118052 | L19: 0.00112587 | M19: 0.00113174 | N19: 0.001015 | O19: 0.001083 | P19: 0.001019 | Q19: 0.00063686 | R19: 0.00067965 | S19: 0.00063951 | T19: 0.001009 | U19: 0.000968 | V19: 0.000923 | W19: 0.00063319 | X19: 0.00060735 | Y19: 0.00057905 | Z19: 0.000416 | AA19: 0.000462 | AB19: 0.000444 | AC19: 0.00026102 | AD19: 0.00029008 | AE19: 0.00027854
... A503: 9910 | B503: 0.001465 | C503: 0.001539 | D503: 0.001439 | E503: 0.00091973 | F503: 0.00096611 | G503: 0.00090339 | H503: 0.003572 | I503: 0.003563 | J503: 0.003603 | K503: 0.00224233 | L503: 0.00223639 | M503: 0.00226181 | N503: 0.000957 | O503: 0.001037 | P503: 0.001032 | Q503: 0.00060076 | R503: 0.00065119 | S503: 0.00064749 | T503: 0.000901 | U503: 0.000873 | V503: 0.000965 | W503: 0.00056525 | X503: 0.00054827 | Y503: 0.00060591 | Z503: 0.0004 | AA503: 0.000399 | AB503: 0.00042 | AC503: 0.00025111 | AD503: 0.00025039 | AE503: 0.00026361
A506: Qwen2-VL + Qwen2.5 — Three-Run Repeatability Summary
A507: Run | B507: P1 EC | C507: P2 EC | D507: P3 EC | E507: P4 EC | F507: P5 EC | G507: Total EC (kWh) | H507: Run | I507: P1 CE | J507: P2 CE | K507: P3 CE | L507: P4 CE | M507: P5 CE | N507: Total CE (kg CO₂eq)
A508: 1 | B508: =SUM(B4:B503) -> 0.798075 | C508: =SUM(H4:H503) -> 1.680026 | D508: =SUM(N4:N503) -> 1.438091 | E508: =SUM(T4:T503) -> 0.960636 | F508: =SUM(Z4:Z503) -> 0.369737 | G508: =SUM(B508:F508) -> 5.246565 | H508: 1 | I508: =SUM(E4:E503) -> 0.49853899 | J508: =SUM(K4:K503) -> 1.054511 | K508: =SUM(Q4:Q503) -> 0.9026562 | L508: =SUM(W4:W503) -> 0.60296798 | M508: =SUM(AC4:AC503) -> 0.23207049 | N508: =SUM(I508:M508) -> 3.2907447
A509: 2 | B509: =SUM(C4:C503) -> 0.795521 | C509: =SUM(I4:I503) -> 1.6746405 | D509: =SUM(O4:O503) -> 1.438546 | E509: =SUM(U4:U503) -> 0.957587 | F509: =SUM(AA4:AA503) -> 0.367223 | G509: =SUM(B509:F509) -> 5.2335175 | H509: 2 | I509: =SUM(F4:F503) -> 0.49933613 | J509: =SUM(L4:L503) -> 1.0504494 | K509: =SUM(R4:R503) -> 0.90066724 | L509: =SUM(X4:X503) -> 0.60105005 | M509: =SUM(AD4:AD503) -> 0.23049723 | N509: =SUM(I509:M509) -> 3.282
A510: 3 | B510: =SUM(D4:D503) -> 0.794308 | C510: =SUM(J4:J503) -> 1.678046 | D510: =SUM(P4:P503) -> 1.437156 | E510: =SUM(V4:V503) -> 0.959509 | F510: =SUM(AB4:AB503) -> 0.365627 | G510: =SUM(B510:F510) -> 5.234646 | H510: 3 | I510: =SUM(G4:G503) -> 0.49856921 | J510: =SUM(M4:M503) -> 1.0532667 | K510: =SUM(S4:S503) -> 0.90206593 | L510: =SUM(Y4:Y503) -> 0.60225782 | M510: =SUM(AE4:AE503) -> 0.22950055 | N510: =SUM(I510:M510) -> 3.2856602

Sheet Five_Metric_Summary
A1: Five Primary Metrics
A4: Configuration | B4: EC Total (kWh) | C4: CE Total (kg CO2eq) | D4: MRC | E4: Phase-5 DIR | F4: SSR
A5: Qwen | B5: =Metrics_Calculation!H4 -> 5.246565 | C5: =Metrics_Calculation!N4 -> 3.2931287 | D5: =Metrics_Calculation!Q4 -> 0.99 | E5: =Metrics_Calculation!U4 -> 0.42983752 | F5: =Metrics_Calculation!X4 -> 0.54623516
A6: Phi-3.5 | B6: =Metrics_Calculation!H5 -> 5.49765 | C6: =Metrics_Calculation!N5 -> 3.4507147 | D6: =Metrics_Calculation!Q5 -> 0.916 | E6: =Metrics_Calculation!U5 -> 0.212086 | F6: =Metrics_Calculation!X5 -> 0.30221759
A7: InternVL + InternLM | B7: =Metrics_Calculation!H6 -> 6.328594 | C7: =Metrics_Calculation!N6 -> 3.9722994 | D7: =Metrics_Calculation!Q6 -> 0.462 | E7: =Metrics_Calculation!U6 -> 0.18878101 | F7: =Metrics_Calculation!X6 -> 0.37135799
A8: InternVL + Mistral | B8: =Metrics_Calculation!H7 -> 5.557654 | C8: =Metrics_Calculation!N7 -> 3.4883947 | D8: =Metrics_Calculation!Q7 -> 0.812 | E8: =Metrics_Calculation!U7 -> 0.16702509 | F8: =Metrics_Calculation!X7 -> 0.49331912
A9: InternVL + Llama-3 | B9: =Metrics_Calculation!H8 -> 7.049798 | C9: =Metrics_Calculation!N8 -> 4.424975 | D9: =Metrics_Calculation!Q8 -> 0.98 | E9: =Metrics_Calculation!U8 -> 0.0036832413 | F9: =Metrics_Calculation!X8 -> 0.46732531
